Traceback (most recent call last):
  File "/home/simul4/Documentos/Cesar/spatiotemporal_FS_HW/Experiments/Paper/CRO_Spatiotemporal_FS_Run1.py", line 38, in <module>
    pred_dataframe = pd.read_csv(path_input+predictor_file, index_col=0)
  File "/home/simul4/.local/lib/python3.9/site-packages/pandas/io/parsers/readers.py", line 912, in read_csv
    return _read(filepath_or_buffer, kwds)
  File "/home/simul4/.local/lib/python3.9/site-packages/pandas/io/parsers/readers.py", line 577, in _read
    parser = TextFileReader(filepath_or_buffer, **kwds)
  File "/home/simul4/.local/lib/python3.9/site-packages/pandas/io/parsers/readers.py", line 1407, in __init__
    self._engine = self._make_engine(f, self.engine)
  File "/home/simul4/.local/lib/python3.9/site-packages/pandas/io/parsers/readers.py", line 1661, in _make_engine
    self.handles = get_handle(
  File "/home/simul4/.local/lib/python3.9/site-packages/pandas/io/common.py", line 859, in get_handle
    handle = open(
FileNotFoundError: [Errno 2] No such file or directory: '../Data/Paper/predictors_dataset.csv'
Traceback (most recent call last):
  File "/home/simul4/Documentos/Cesar/spatiotemporal_FS_HW/Experiments/Paper/CRO_Spatiotemporal_FS_Run1.py", line 38, in <module>
    pred_dataframe = pd.read_csv(path_input+predictor_file, index_col=0)
  File "/home/simul4/.local/lib/python3.9/site-packages/pandas/io/parsers/readers.py", line 912, in read_csv
    return _read(filepath_or_buffer, kwds)
  File "/home/simul4/.local/lib/python3.9/site-packages/pandas/io/parsers/readers.py", line 577, in _read
    parser = TextFileReader(filepath_or_buffer, **kwds)
  File "/home/simul4/.local/lib/python3.9/site-packages/pandas/io/parsers/readers.py", line 1407, in __init__
    self._engine = self._make_engine(f, self.engine)
  File "/home/simul4/.local/lib/python3.9/site-packages/pandas/io/parsers/readers.py", line 1661, in _make_engine
    self.handles = get_handle(
  File "/home/simul4/.local/lib/python3.9/site-packages/pandas/io/common.py", line 859, in get_handle
    handle = open(
FileNotFoundError: [Errno 2] No such file or directory: '../../Data/Paper/predictors_dataset.csv'
Traceback (most recent call last):
  File "/home/simul4/Documentos/Cesar/spatiotemporal_FS_HW/Experiments/Paper/CRO_Spatiotemporal_FS_Run2.py", line 1, in <module>
    from PyCROSL.CRO_SL import *
ModuleNotFoundError: No module named 'PyCROSL'
Traceback (most recent call last):
  File "/home/simul4/Documentos/Cesar/spatiotemporal_FS_HW/Experiments/Paper/CRO_Spatiotemporal_FS_Run3.py", line 1, in <module>
    from PyCROSL.CRO_SL import *
ModuleNotFoundError: No module named 'PyCROSL'
Traceback (most recent call last):
  File "/home/simul4/Documentos/Cesar/spatiotemporal_FS_HW/Experiments/Paper/CRO_Spatiotemporal_FS_Run4.py", line 1, in <module>
    from PyCROSL.CRO_SL import *
ModuleNotFoundError: No module named 'PyCROSL'
Traceback (most recent call last):
  File "/home/simul4/Documentos/Cesar/spatiotemporal_FS_HW/Experiments/Paper/CRO_Spatiotemporal_FS_Run5.py", line 1, in <module>
    from PyCROSL.CRO_SL import *
ModuleNotFoundError: No module named 'PyCROSL'
Traceback (most recent call last):
  File "/home/simul4/Documentos/Cesar/spatiotemporal_FS_HW/Experiments/Paper/CRO_Spatiotemporal_FS_Run6.py", line 1, in <module>
    from PyCROSL.CRO_SL import *
ModuleNotFoundError: No module named 'PyCROSL'
Traceback (most recent call last):
  File "/home/simul4/Documentos/Cesar/spatiotemporal_FS_HW/Experiments/Paper/CRO_Spatiotemporal_FS_Run7.py", line 1, in <module>
    from PyCROSL.CRO_SL import *
ModuleNotFoundError: No module named 'PyCROSL'
Traceback (most recent call last):
  File "/home/simul4/Documentos/Cesar/spatiotemporal_FS_HW/Experiments/Paper/CRO_Spatiotemporal_FS_Run8.py", line 1, in <module>
    from PyCROSL.CRO_SL import *
ModuleNotFoundError: No module named 'PyCROSL'
Traceback (most recent call last):
  File "/home/simul4/Documentos/Cesar/spatiotemporal_FS_HW/Experiments/Paper/CRO_Spatiotemporal_FS_Run9.py", line 1, in <module>
    from PyCROSL.CRO_SL import *
ModuleNotFoundError: No module named 'PyCROSL'
Traceback (most recent call last):
  File "/home/simul4/Documentos/Cesar/spatiotemporal_FS_HW/Experiments/Paper/CRO_Spatiotemporal_FS_Run10.py", line 1, in <module>
    from PyCROSL.CRO_SL import *
ModuleNotFoundError: No module named 'PyCROSL'
