Number of clusters: 10, basin GLB
Traceback (most recent call last):
  File "/opt/miniconda3/envs/weather/lib/python3.11/site-packages/pandas/core/indexes/base.py", line 3802, in get_loc
    return self._engine.get_loc(casted_key)
           ^^^^^^^^^^^^^^^^^^^^^^^^^^^^^^^^
  File "index.pyx", line 153, in pandas._libs.index.IndexEngine.get_loc
  File "index.pyx", line 182, in pandas._libs.index.IndexEngine.get_loc
  File "pandas/_libs/hashtable_class_helper.pxi", line 7081, in pandas._libs.hashtable.PyObjectHashTable.get_item
  File "pandas/_libs/hashtable_class_helper.pxi", line 7089, in pandas._libs.hashtable.PyObjectHashTable.get_item
KeyError: 'Metric'

The above exception was the direct cause of the following exception:

Traceback (most recent call last):
  File "/Users/huripari/Documents/PhD/TCs_Genesis/FS_TCG/test_results_analysis.py", line 417, in <module>
    main(args.basin, args.n_clusters, args.n_vars, args.n_idxs, args.results_folder, args.model_kind, args.n_folds, args.start_year, args.end_year)
  File "/Users/huripari/Documents/PhD/TCs_Genesis/FS_TCG/test_results_analysis.py", line 64, in main
    MetricBest = sol_file_df['Metric'].idxmin() 
                 ~~~~~~~~~~~^^^^^^^^^^
  File "/opt/miniconda3/envs/weather/lib/python3.11/site-packages/pandas/core/frame.py", line 4090, in __getitem__
    indexer = self.columns.get_loc(key)
              ^^^^^^^^^^^^^^^^^^^^^^^^^
  File "/opt/miniconda3/envs/weather/lib/python3.11/site-packages/pandas/core/indexes/base.py", line 3809, in get_loc
    raise KeyError(key) from err
KeyError: 'Metric'
Traceback (most recent call last):
  File "/opt/miniconda3/envs/weather/lib/python3.11/site-packages/pandas/core/indexes/base.py", line 3802, in get_loc
    return self._engine.get_loc(casted_key)
           ^^^^^^^^^^^^^^^^^^^^^^^^^^^^^^^^
  File "index.pyx", line 153, in pandas._libs.index.IndexEngine.get_loc
  File "index.pyx", line 182, in pandas._libs.index.IndexEngine.get_loc
  File "pandas/_libs/hashtable_class_helper.pxi", line 7081, in pandas._libs.hashtable.PyObjectHashTable.get_item
  File "pandas/_libs/hashtable_class_helper.pxi", line 7089, in pandas._libs.hashtable.PyObjectHashTable.get_item
KeyError: 'Metric'

The above exception was the direct cause of the following exception:

Traceback (most recent call last):
  File "/Users/huripari/Documents/PhD/TCs_Genesis/FS_TCG/test_results_analysis.py", line 417, in <module>
    main(args.basin, args.n_clusters, args.n_vars, args.n_idxs, args.results_folder, args.model_kind, args.n_folds, args.start_year, args.end_year)
  File "/Users/huripari/Documents/PhD/TCs_Genesis/FS_TCG/test_results_analysis.py", line 64, in main
    MetricBest = sol_file_df['Metric'].idxmin() 
                 ~~~~~~~~~~~^^^^^^^^^^
  File "/opt/miniconda3/envs/weather/lib/python3.11/site-packages/pandas/core/frame.py", line 4090, in __getitem__
    indexer = self.columns.get_loc(key)
              ^^^^^^^^^^^^^^^^^^^^^^^^^
  File "/opt/miniconda3/envs/weather/lib/python3.11/site-packages/pandas/core/indexes/base.py", line 3809, in get_loc
    raise KeyError(key) from err
KeyError: 'Metric'
Number of clusters: 10, basin GLB
Traceback (most recent call last):
  File "/opt/miniconda3/envs/weather/lib/python3.11/site-packages/pandas/core/indexes/base.py", line 3802, in get_loc
    return self._engine.get_loc(casted_key)
           ^^^^^^^^^^^^^^^^^^^^^^^^^^^^^^^^
  File "index.pyx", line 153, in pandas._libs.index.IndexEngine.get_loc
  File "index.pyx", line 182, in pandas._libs.index.IndexEngine.get_loc
  File "pandas/_libs/hashtable_class_helper.pxi", line 7081, in pandas._libs.hashtable.PyObjectHashTable.get_item
  File "pandas/_libs/hashtable_class_helper.pxi", line 7089, in pandas._libs.hashtable.PyObjectHashTable.get_item
KeyError: 'Metric'

The above exception was the direct cause of the following exception:

Traceback (most recent call last):
  File "/Users/huripari/Documents/PhD/TCs_Genesis/FS_TCG/test_results_analysis.py", line 417, in <module>
    main(args.basin, args.n_clusters, args.n_vars, args.n_idxs, args.results_folder, args.model_kind, args.n_folds, args.start_year, args.end_year)
  File "/Users/huripari/Documents/PhD/TCs_Genesis/FS_TCG/test_results_analysis.py", line 64, in main
    MetricBest = sol_file_df['Metric'].idxmin() 
                 ~~~~~~~~~~~^^^^^^^^^^
  File "/opt/miniconda3/envs/weather/lib/python3.11/site-packages/pandas/core/frame.py", line 4090, in __getitem__
    indexer = self.columns.get_loc(key)
              ^^^^^^^^^^^^^^^^^^^^^^^^^
  File "/opt/miniconda3/envs/weather/lib/python3.11/site-packages/pandas/core/indexes/base.py", line 3809, in get_loc
    raise KeyError(key) from err
KeyError: 'Metric'
Traceback (most recent call last):
  File "/opt/miniconda3/envs/weather/lib/python3.11/site-packages/pandas/core/indexes/base.py", line 3802, in get_loc
    return self._engine.get_loc(casted_key)
           ^^^^^^^^^^^^^^^^^^^^^^^^^^^^^^^^
  File "index.pyx", line 153, in pandas._libs.index.IndexEngine.get_loc
  File "index.pyx", line 182, in pandas._libs.index.IndexEngine.get_loc
  File "pandas/_libs/hashtable_class_helper.pxi", line 7081, in pandas._libs.hashtable.PyObjectHashTable.get_item
  File "pandas/_libs/hashtable_class_helper.pxi", line 7089, in pandas._libs.hashtable.PyObjectHashTable.get_item
KeyError: 'Metric'

The above exception was the direct cause of the following exception:

Traceback (most recent call last):
  File "/Users/huripari/Documents/PhD/TCs_Genesis/FS_TCG/test_results_analysis.py", line 417, in <module>
    main(args.basin, args.n_clusters, args.n_vars, args.n_idxs, args.results_folder, args.model_kind, args.n_folds, args.start_year, args.end_year)
  File "/Users/huripari/Documents/PhD/TCs_Genesis/FS_TCG/test_results_analysis.py", line 64, in main
    MetricBest = sol_file_df['Metric'].idxmin() 
                 ~~~~~~~~~~~^^^^^^^^^^
  File "/opt/miniconda3/envs/weather/lib/python3.11/site-packages/pandas/core/frame.py", line 4090, in __getitem__
    indexer = self.columns.get_loc(key)
              ^^^^^^^^^^^^^^^^^^^^^^^^^
  File "/opt/miniconda3/envs/weather/lib/python3.11/site-packages/pandas/core/indexes/base.py", line 3809, in get_loc
    raise KeyError(key) from err
KeyError: 'Metric'
Number of clusters: 10, basin GLB
Traceback (most recent call last):
  File "/opt/miniconda3/envs/weather/lib/python3.11/site-packages/pandas/core/indexes/base.py", line 3802, in get_loc
    return self._engine.get_loc(casted_key)
           ^^^^^^^^^^^^^^^^^^^^^^^^^^^^^^^^
  File "index.pyx", line 153, in pandas._libs.index.IndexEngine.get_loc
  File "index.pyx", line 182, in pandas._libs.index.IndexEngine.get_loc
  File "pandas/_libs/hashtable_class_helper.pxi", line 7081, in pandas._libs.hashtable.PyObjectHashTable.get_item
  File "pandas/_libs/hashtable_class_helper.pxi", line 7089, in pandas._libs.hashtable.PyObjectHashTable.get_item
KeyError: 'Metric'

The above exception was the direct cause of the following exception:

Traceback (most recent call last):
  File "/Users/huripari/Documents/PhD/TCs_Genesis/FS_TCG/test_results_analysis.py", line 417, in <module>
    main(args.basin, args.n_clusters, args.n_vars, args.n_idxs, args.results_folder, args.model_kind, args.n_folds, args.start_year, args.end_year)
  File "/Users/huripari/Documents/PhD/TCs_Genesis/FS_TCG/test_results_analysis.py", line 64, in main
    MetricBest = sol_file_df['Metric'].idxmin() 
                 ~~~~~~~~~~~^^^^^^^^^^
  File "/opt/miniconda3/envs/weather/lib/python3.11/site-packages/pandas/core/frame.py", line 4090, in __getitem__
    indexer = self.columns.get_loc(key)
              ^^^^^^^^^^^^^^^^^^^^^^^^^
  File "/opt/miniconda3/envs/weather/lib/python3.11/site-packages/pandas/core/indexes/base.py", line 3809, in get_loc
    raise KeyError(key) from err
KeyError: 'Metric'
Traceback (most recent call last):
  File "/opt/miniconda3/envs/weather/lib/python3.11/site-packages/pandas/core/indexes/base.py", line 3802, in get_loc
    return self._engine.get_loc(casted_key)
           ^^^^^^^^^^^^^^^^^^^^^^^^^^^^^^^^
  File "index.pyx", line 153, in pandas._libs.index.IndexEngine.get_loc
  File "index.pyx", line 182, in pandas._libs.index.IndexEngine.get_loc
  File "pandas/_libs/hashtable_class_helper.pxi", line 7081, in pandas._libs.hashtable.PyObjectHashTable.get_item
  File "pandas/_libs/hashtable_class_helper.pxi", line 7089, in pandas._libs.hashtable.PyObjectHashTable.get_item
KeyError: 'Metric'

The above exception was the direct cause of the following exception:

Traceback (most recent call last):
  File "/Users/huripari/Documents/PhD/TCs_Genesis/FS_TCG/test_results_analysis.py", line 417, in <module>
    main(args.basin, args.n_clusters, args.n_vars, args.n_idxs, args.results_folder, args.model_kind, args.n_folds, args.start_year, args.end_year)
  File "/Users/huripari/Documents/PhD/TCs_Genesis/FS_TCG/test_results_analysis.py", line 64, in main
    MetricBest = sol_file_df['Metric'].idxmin() 
                 ~~~~~~~~~~~^^^^^^^^^^
  File "/opt/miniconda3/envs/weather/lib/python3.11/site-packages/pandas/core/frame.py", line 4090, in __getitem__
    indexer = self.columns.get_loc(key)
              ^^^^^^^^^^^^^^^^^^^^^^^^^
  File "/opt/miniconda3/envs/weather/lib/python3.11/site-packages/pandas/core/indexes/base.py", line 3809, in get_loc
    raise KeyError(key) from err
KeyError: 'Metric'
Number of clusters: 10, basin GLB
Traceback (most recent call last):
  File "/opt/miniconda3/envs/weather/lib/python3.11/site-packages/pandas/core/indexes/base.py", line 3802, in get_loc
    return self._engine.get_loc(casted_key)
           ^^^^^^^^^^^^^^^^^^^^^^^^^^^^^^^^
  File "index.pyx", line 153, in pandas._libs.index.IndexEngine.get_loc
  File "index.pyx", line 182, in pandas._libs.index.IndexEngine.get_loc
  File "pandas/_libs/hashtable_class_helper.pxi", line 7081, in pandas._libs.hashtable.PyObjectHashTable.get_item
  File "pandas/_libs/hashtable_class_helper.pxi", line 7089, in pandas._libs.hashtable.PyObjectHashTable.get_item
KeyError: 'Metric'

The above exception was the direct cause of the following exception:

Traceback (most recent call last):
  File "/Users/huripari/Documents/PhD/TCs_Genesis/FS_TCG/test_results_analysis.py", line 417, in <module>
    main(args.basin, args.n_clusters, args.n_vars, args.n_idxs, args.results_folder, args.model_kind, args.n_folds, args.start_year, args.end_year)
  File "/Users/huripari/Documents/PhD/TCs_Genesis/FS_TCG/test_results_analysis.py", line 64, in main
    MetricBest = sol_file_df['Metric'].idxmin() 
                 ~~~~~~~~~~~^^^^^^^^^^
  File "/opt/miniconda3/envs/weather/lib/python3.11/site-packages/pandas/core/frame.py", line 4090, in __getitem__
    indexer = self.columns.get_loc(key)
              ^^^^^^^^^^^^^^^^^^^^^^^^^
  File "/opt/miniconda3/envs/weather/lib/python3.11/site-packages/pandas/core/indexes/base.py", line 3809, in get_loc
    raise KeyError(key) from err
KeyError: 'Metric'
Traceback (most recent call last):
  File "/opt/miniconda3/envs/weather/lib/python3.11/site-packages/pandas/core/indexes/base.py", line 3802, in get_loc
    return self._engine.get_loc(casted_key)
           ^^^^^^^^^^^^^^^^^^^^^^^^^^^^^^^^
  File "index.pyx", line 153, in pandas._libs.index.IndexEngine.get_loc
  File "index.pyx", line 182, in pandas._libs.index.IndexEngine.get_loc
  File "pandas/_libs/hashtable_class_helper.pxi", line 7081, in pandas._libs.hashtable.PyObjectHashTable.get_item
  File "pandas/_libs/hashtable_class_helper.pxi", line 7089, in pandas._libs.hashtable.PyObjectHashTable.get_item
KeyError: 'Metric'

The above exception was the direct cause of the following exception:

Traceback (most recent call last):
  File "/Users/huripari/Documents/PhD/TCs_Genesis/FS_TCG/test_results_analysis.py", line 417, in <module>
    main(args.basin, args.n_clusters, args.n_vars, args.n_idxs, args.results_folder, args.model_kind, args.n_folds, args.start_year, args.end_year)
  File "/Users/huripari/Documents/PhD/TCs_Genesis/FS_TCG/test_results_analysis.py", line 64, in main
    MetricBest = sol_file_df['Metric'].idxmin() 
                 ~~~~~~~~~~~^^^^^^^^^^
  File "/opt/miniconda3/envs/weather/lib/python3.11/site-packages/pandas/core/frame.py", line 4090, in __getitem__
    indexer = self.columns.get_loc(key)
              ^^^^^^^^^^^^^^^^^^^^^^^^^
  File "/opt/miniconda3/envs/weather/lib/python3.11/site-packages/pandas/core/indexes/base.py", line 3809, in get_loc
    raise KeyError(key) from err
KeyError: 'Metric'
Number of clusters: 10, basin GLB
Traceback (most recent call last):
  File "/opt/miniconda3/envs/weather/lib/python3.11/site-packages/pandas/core/indexes/base.py", line 3802, in get_loc
    return self._engine.get_loc(casted_key)
           ^^^^^^^^^^^^^^^^^^^^^^^^^^^^^^^^
  File "index.pyx", line 153, in pandas._libs.index.IndexEngine.get_loc
  File "index.pyx", line 182, in pandas._libs.index.IndexEngine.get_loc
  File "pandas/_libs/hashtable_class_helper.pxi", line 7081, in pandas._libs.hashtable.PyObjectHashTable.get_item
  File "pandas/_libs/hashtable_class_helper.pxi", line 7089, in pandas._libs.hashtable.PyObjectHashTable.get_item
KeyError: 'Metric'

The above exception was the direct cause of the following exception:

Traceback (most recent call last):
  File "/Users/huripari/Documents/PhD/TCs_Genesis/FS_TCG/test_results_analysis.py", line 417, in <module>
    main(args.basin, args.n_clusters, args.n_vars, args.n_idxs, args.results_folder, args.model_kind, args.n_folds, args.start_year, args.end_year)
  File "/Users/huripari/Documents/PhD/TCs_Genesis/FS_TCG/test_results_analysis.py", line 64, in main
    MetricBest = sol_file_df['Metric'].idxmin() 
                 ~~~~~~~~~~~^^^^^^^^^^
  File "/opt/miniconda3/envs/weather/lib/python3.11/site-packages/pandas/core/frame.py", line 4090, in __getitem__
    indexer = self.columns.get_loc(key)
              ^^^^^^^^^^^^^^^^^^^^^^^^^
  File "/opt/miniconda3/envs/weather/lib/python3.11/site-packages/pandas/core/indexes/base.py", line 3809, in get_loc
    raise KeyError(key) from err
KeyError: 'Metric'
Traceback (most recent call last):
  File "/opt/miniconda3/envs/weather/lib/python3.11/site-packages/pandas/core/indexes/base.py", line 3802, in get_loc
    return self._engine.get_loc(casted_key)
           ^^^^^^^^^^^^^^^^^^^^^^^^^^^^^^^^
  File "index.pyx", line 153, in pandas._libs.index.IndexEngine.get_loc
  File "index.pyx", line 182, in pandas._libs.index.IndexEngine.get_loc
  File "pandas/_libs/hashtable_class_helper.pxi", line 7081, in pandas._libs.hashtable.PyObjectHashTable.get_item
  File "pandas/_libs/hashtable_class_helper.pxi", line 7089, in pandas._libs.hashtable.PyObjectHashTable.get_item
KeyError: 'Metric'

The above exception was the direct cause of the following exception:

Traceback (most recent call last):
  File "/Users/huripari/Documents/PhD/TCs_Genesis/FS_TCG/test_results_analysis.py", line 417, in <module>
    main(args.basin, args.n_clusters, args.n_vars, args.n_idxs, args.results_folder, args.model_kind, args.n_folds, args.start_year, args.end_year)
  File "/Users/huripari/Documents/PhD/TCs_Genesis/FS_TCG/test_results_analysis.py", line 64, in main
    MetricBest = sol_file_df['Metric'].idxmin() 
                 ~~~~~~~~~~~^^^^^^^^^^
  File "/opt/miniconda3/envs/weather/lib/python3.11/site-packages/pandas/core/frame.py", line 4090, in __getitem__
    indexer = self.columns.get_loc(key)
              ^^^^^^^^^^^^^^^^^^^^^^^^^
  File "/opt/miniconda3/envs/weather/lib/python3.11/site-packages/pandas/core/indexes/base.py", line 3809, in get_loc
    raise KeyError(key) from err
KeyError: 'Metric'
